Workbook

Sheet Synthèse
A1: Clients potentiels MINYALA — au 13/10/2026
A2: Photo à date, sans tarif professionnel : peut être partagée ou analysée (par exemple dans ChatGPT). Le suivi au jour le jour reste dans prospects-minyala.xlsx.
A4: Clients potentiels
A5: Total | B5: =COUNTA('Tous les clients'!E2:E400)
A6: Pros France — Île-de-France | B6: =COUNTIFS('Tous les clients'!B2:B400,"Pro France",'Tous les clients'!G2:G400,"Île-de-France")
A7: Pros France — Normandie | B7: =COUNTIFS('Tous les clients'!B2:B400,"Pro France",'Tous les clients'!G2:G400,"Normandie")
A8: Acheteurs export (demandes RFQ) | B8: =COUNTIF('Tous les clients'!B2:B400,"Acheteur export (RFQ)")
A9: Priorité 1 | B9: =COUNTIF('Tous les clients'!C2:C400,1)
A10: Contactés (statut ≠ À contacter / À étudier) | B10: =COUNTA('Tous les clients'!L2:L400)-COUNTIF('Tous les clients'!L2:L400,"À contacter")-COUNTIF('Tous les clients'!L2:L400,"À étudier")
A12: Par type d'acheteur (pros France)
A13: Paysagiste | B13: =COUNTIF('Tous les clients'!D2:D400,"Paysagiste")
A14: Pisciniste | B14: =COUNTIF('Tous les clients'!D2:D400,"Pisciniste")
A15: Négoce / revendeur | B15: =COUNTIF('Tous les clients'!D2:D400,"Négoce / revendeur")
A16: Showroom carrelage | B16: =COUNTIF('Tous les clients'!D2:D400,"Showroom carrelage")
A17: Marbrerie | B17: =COUNTIF('Tous les clients'!D2:D400,"Marbrerie")
A18: Carreleur / poseur pierre | B18: =COUNTIF('Tous les clients'!D2:D400,"Carreleur / poseur pierre")
A19: Rénovation haut de gamme | B19: =COUNTIF('Tous les clients'!D2:D400,"Rénovation haut de gamme")
A20: Constructeur de maisons | B20: =COUNTIF('Tous les clients'!D2:D400,"Constructeur de maisons")
A21: Architecte d'intérieur | B21: =COUNTIF('Tous les clients'!D2:D400,"Architecte d'intérieur")
A22: Spa / hammam | B22: =COUNTIF('Tous les clients'!D2:D400,"Spa / hammam")
A23: Maître d'œuvre | B23: =COUNTIF('Tous les clients'!D2:D400,"Maître d'œuvre")
A24: Jardinerie / matériaux paysage | B24: =COUNTIF('Tous les clients'!D2:D400,"Jardinerie / matériaux paysage")
A25: Hôtel / restaurant | B25: =COUNTIF('Tous les clients'!D2:D400,"Hôtel / restaurant")
A26: Architecte | B26: =COUNTIF('Tous les clients'!D2:D400,"Architecte")
A27: Promoteur | B27: =COUNTIF('Tous les clients'!D2:D400,"Promoteur")
A28: Salle de bains | B28: =COUNTIF('Tous les clients'!D2:D400,"Salle de bains")
A29: Entreprise bâtiment | B29: =COUNTIF('Tous les clients'!D2:D400,"Entreprise bâtiment")
A30: Travaux publics / VRD | B30: =COUNTIF('Tous les clients'!D2:D400,"Travaux publics / VRD")
A32: Canaux de vente — vérification au 13/10/2026
A33: Canal | B33: Verdict | C33: Pourquoi | D33: Guide
A34: Professionnels France (e-mail, téléphone, visite) | B34: OUI — priorité | C34: 197 entreprises vérifiées (négoces, showrooms, marbreries, piscinistes, paysagistes…). Message prêt dans kit-de-vente.md, section 4. Autorisé si le message concerne leur métier, avec possibilité de refuser. | D34: kit-de-vente.md
A35: Leboncoin (compte Pro) | B35: OUI — une annonce, après vraies photos et IDU | C35: Compte Pro gratuit, 50 dépôts offerts. Une annonce à Gennevilliers, lot de 25 m² à 875 €. Pas de lien vers la boutique ni de paiement en ligne Leboncoin pour l'instant (12 % de commission, 14 jours de rétractation). | D35: leboncoin.md
A36: Facebook et Instagram | B36: OUI, après correction des CGV du site | C36: Page, publicités locales et groupes avec accord des admins. Publication Instagram prête (en attente de votre accord). | D36: facebook-instagram.md
A37: Demandes RFQ (StoneAdd, StoneContact…) | B37: À étudier | C37: 52 demandes d'acheteurs étrangers ; 5 à forte correspondance. Attention aux arnaques (avance de frais, faux justificatifs). | D37: rfq-kit.md
A38: AlloVoisins | B38: NON (au plus l'essai gratuit) | C38: Compte pro gratuit : aucune réponse possible. Premier : 12 mois d'engagement, dès 29,99 €/mois ou 99,99 € HT/mois. Demandes locales = pose, pas achat de pierre. | D38: allovoisins.md
A39: Amazon | B39: NON pour l'instant | C39: Lots de 25 m² (≈ 1,25 t) inadaptés : pas de retrait, livraison lourde sur invitation, commission de 13–15 % aussi sur le port ; il reste 8 à 19 €/m² HT contre 29 € en vente directe. Au mieux plus tard : un échantillon en colis. | D39: amazon.md
A40: ChatGPT (via Shopify) | B40: NON pour l'instant | C40: Le canal ChatGPT de Shopify est réservé aux boutiques qui vendent aux États-Unis (achat via les IA : acheteurs américains seulement). Reste la visibilité gratuite dans les réponses de recherche de ChatGPT. À faire : masquer les produits « Acompte », remplir les CGV, ajouter des photos.
A41: ZIM (fret maritime) | B41: Import, pas un canal de vente | C41: Pour faire venir un conteneur Damiette → Le Havre : ≈ 450–485 m² par 20', droits 0 % avec EUR.1. | D41: fret-zim.md
A43: À régler avant de vendre (tous canaux)
A44: • | B44: Activité : vente de pierre déclarée au guichet unique le 13/09/2026 (formalité Y00280607979), pas encore visible au registre le 13/10/2026 : vérifier son statut et répondre à toute demande de régularisation. Déclarer aussi le dépôt de Gennevilliers et le nom de domaine pierredegypte.online.
...

Sheet Tous les clients
A1: N° | B1: Catégorie | C1: Priorité | D1: Type | E1: Entreprise ou demande | F1: Ville / pays | G1: Zone | H1: Pourquoi les contacter / ce qu'ils cherchent | I1: Site web | J1: Téléphone | K1: Source | L1: Statut | M1: Date du contact | N1: Prochaine action | O1: Notes | P1: Liste | Q1: E-mail (contact)
A2: 1 | B2: Pro France | C2: 1 | D2: Jardinerie / matériaux paysage | E2: ABL Négoce | F2: Le Molay-Littry (14330) | G2: Normandie | H2: Négoce d'aménagement extérieur du Calvados qui vend déjà des pierres naturelles à des paysagistes, architectes et collectivités : il pourrait ajouter MINYALA à sa gamme. | I2: www.abl-negoce.fr | J2: 02 31 22 96 12 | K2: Voir | L2: Contacté | M2: 12/10/2026 | N2: Vérifier la réponse dans la boîte Hotmail d'envoi ; une seule relance (~19/10) si silence | O2: E-mail de prospection (tarif pro) du 12/10/2026 à 14:59 (copie reçue en INBOX). | P2: 3e liste (12/10) | Q2: contact@ablnegoce.fr
A3: 2 | B3: Pro France | C3: 1 | D3: Négoce / revendeur | E3: BigMat MVR Matériaux | F3: Évreux (27000) | G3: Normandie | H3: Ce négoce BigMat de 8 magasins dans l'Eure et en Seine-Maritime vend carrelages et dallages et peut acheter un lot de MINYALA pour tout son réseau. | I3: magasins.bigmat.fr/normandie/eure/evreux/bigmat-evreux-mvr-materiaux-144 | J3: 02 32 31 20 17 | K3: Voir | L3: À contacter | O3: [13/10] Aucun e-mail publié : formulaire de la fiche magasin BigMat Évreux uniquement. | P3: 2e liste (12/10)
A4: 3 | B4: Pro France | C4: 1 | D4: Showroom carrelage | E4: Carrelages Dente | F4: Yvetot (76190) | G4: Normandie | H4: Spécialiste du carrelage à Yvetot depuis 1959, avec grand showroom, déstockage et pierres naturelles déjà en gamme : il pourrait acheter MINYALA en lot pour l'intérieur et la terrasse. | I4: www.carrelages-dente.fr | J4: 02 35 56 87 87 | K4: Voir | L4: Contacté | M4: 12/10/2026 | N4: Vérifier la réponse dans la boîte Hotmail d'envoi ; une seule relance (~19/10) si silence | O4: E-mail de prospection (tarif pro) du 12/10/2026 à 15:00 (copie reçue en SPAM). | P4: 3e liste (12/10) | Q4: carrelagesdente@gmail.com
A5: 4 | B5: Pro France | C5: 1 | D5: Négoce / revendeur | E5: Le Comptoir du Sol | F5: Rouen et Dieppe (siège 76370 Neuville-lès-Dieppe) | G5: Normandie | H5: Showrooms carrelage et dallage, dont pierre naturelle et dallage terrasse. | J5: 02 79 02 73 91 | K5: Voir | L5: À contacter | N5: Prochain contact depuis la boîte Gmail (pas Hotmail), après fusion du suivi | O5: Rapprochement du 13/10 (autre assistant) : dernier envoi rejeté (échec de remise) — à confirmer, puis trouver une autre adresse. | [13/10] Tentative depuis Hotmail rejetée EN SORTIE (5.7.520 : contenu classé spam par Microsoft) — message non remis ; l'adresse n'est pas forcément invalide. Prochain contact depuis la boîte Gmail, nouveau modèle, jamais depuis Hotmail. | P5: 1re liste (08/10) | Q5: contact@lecomptoirdusol.com
A6: 5 | B6: Pro France | C6: 1 | D6: Négoce / revendeur | E6: Le Monde de la Pierre | F6: Rolleville (76133) | G6: Normandie | H6: Ce négociant en pierre naturelle près du Havre fait aussi des dallages et des aménagements extérieurs : il peut racheter un lot de calcaire égyptien MINYALA. | I6: www.lemondedelapierre.fr | J6: 02 35 53 15 31 | K6: Voir | L6: Contacté | M6: 12-13/10/2026 | N6: Pas de relance avant le rapprochement de l'export Hotmail ; ensuite, contact depuis la boîte Gmail uniquement | O6: [13/10] Page contact (bureau) ; devis/atelier : deco@lemondedelapierre.fr. | [13/10 soir] Correctif : un envoi vers contact@lemondedelapierre.fr est recensé dans l'export de la boîte Hotmail (remise non confirmée, pas de copie Gmail) — ne plus compter « jamais contacté » ; date exacte à confirmer au rapprochement de l'export. | P6: 2e liste (12/10) | Q6: contact@lemondedelapierre.fr
A7: 6 | B7: Pro France | C7: 1 | D7: Négoce / revendeur | E7: Midi Carrelage | F7: Sotteville-lès-Rouen (76300) | G7: Normandie | H7: Spécialiste carrelage et salle de bains depuis plus de 30 ans, avec espace pro et showroom, qui vend déjà du dallage en pierre, il pourrait référencer MINYALA pour ses clients artisans et particuliers. | I7: www.midi-carrelage.fr | J7: 02 35 65 27 40 | K7: Voir | L7: À contacter | N7: Prochain contact depuis la boîte Gmail (pas Hotmail), après fusion du suivi | O7: [13/10] Tentative depuis Hotmail rejetée EN SORTIE (5.7.520 : contenu classé spam par Microsoft) — message non remis ; l'adresse n'est pas forcément invalide. Prochain contact depuis la boîte Gmail, nouveau modèle, jamais depuis Hotmail. | P7: 3e liste (12/10) | Q7: contact.midicarrelage@midicarrelage.fr
A8: 7 | B8: Pro France | C8: 1 | D8: Showroom carrelage | E8: Nivault | F8: Bénouville (14970) | G8: Normandie | H8: Magasin de carrelage près de Caen avec un showroom de 1 000 m² et une offre de dalles de terrasse : il pourrait exposer et revendre MINYALA en intérieur et en extérieur. | I8: www.nivault.com | J8: 02 31 46 12 34 | K8: Voir | L8: Contacté | M8: 12/10/2026 | N8: Vérifier la réponse dans la boîte Hotmail d'envoi ; une seule relance (~19/10) si silence | O8: E-mail de prospection (tarif pro) du 12/10/2026 à 14:59 (copie reçue en SPAM). | P8: 3e liste (12/10) | Q8: info@nivault.com
A9: 8 | B9: Pro France | C9: 1 | D9: Paysagiste | E9: Paysages Conseil – Agence de Caen | F9: Caen (14000) | G9: Normandie | H9: Gros paysagiste normand (75 compagnons, plusieurs agences) qui réalise des terrasses en pierre naturelle et des aménagements autour des piscines et spas, MINYALA pourrait servir sur ses chantiers (usage à valider avec lui : finition, gel, glissance, humidité). | I9: www.paysagesconseil.fr/paysagiste-caen | J9: 02 31 68 69 68 | K9: Voir | L9: À contacter | P9: 3e liste (12/10)
A10: 9 | B10: Pro France | C10: 1 | D10: Négoce / revendeur | E10: Pillaud Matériaux (agence de Caen) | F10: Cormelles-le-Royal (14123) | G10: Normandie | H10: Ce négoce de 29 agences, dont Caen, Le Havre, Lisieux et Pont-Audemer, vend déjà des dalles et pierres pour terrasses et peut prendre un lot entier de MINYALA. | I10: www.pillaud-materiaux.com | J10: 02 31 82 44 35 | K10: Voir | L10: À contacter | O10: [13/10] Page agence de Caen du site Pillaud. | P10: 2e liste (12/10) | Q10: caen@pillaud.fr
A11: 10 | B11: Pro France | C11: 1 | D11: Promoteur | E11: Sedelka | F11: Caen | G11: Normandie | H11: Promoteur avec un showroom dans chaque agence où les acquéreurs choisissent carrelage et parquet : MINYALA pourrait y entrer comme option de sol en pierre naturelle sur ses programmes normands. | I11: www.sedelka.fr | J11: 02 31 08 34 88 | K11: Voir | L11: À contacter | P11: 3e liste (12/10)
A12: 11 | B12: Pro France | C12: 1 | D12: Négoce / revendeur | E12: Solmur (agence d'Évreux) | F12: Évreux (27000) | G12: Normandie | H12: Agence d'un distributeur régional de revêtements qui vend déjà carrelage extérieur et travertin : elle pourrait revendre MINYALA à Évreux et dans l'Eure. | I12: www.solmur.fr | K12: Voir | L12: À contacter | P12: 3e liste (12/10)
A13: 12 | B13: Pro France | C13: 1 | D13: Showroom carrelage | E13: Tendance Carrelage Rouen | F13: Rouen (76000) | G13: Normandie | H13: Showroom rouennais de carrelages et pierres naturelles qui vend déjà marbre et dalles de terrasse de 2 cm : il pourrait ajouter MINYALA à sa gamme pierre. | I13: www.tendancecarrelagesrouen.fr | J13: 02 35 36 36 36 | K13: Voir | L13: À contacter | P13: 3e liste (12/10)
A14: 13 | B14: Pro France | C14: 1 | D14: Showroom carrelage | E14: Torchio (showroom Caen/Ifs) | F14: Ifs (14123) | G14: Normandie | H14: Ce spécialiste du carrelage intérieur et extérieur, avec 9 showrooms et un réseau de poseurs partenaires, peut acheter un lot de MINYALA pour ses terrasses. | I14: www.torchio.fr | J14: 02 31 35 05 05 | K14: Voir | L14: À contacter | O14: [13/10] Affiché en forme anti-spam « info[@]torchio.fr » sur les mentions légales du site. | P14: 2e liste (12/10) | Q14: info@torchio.fr
A15: 14 | B15: Pro France | C15: 1 | D15: Carreleur / poseur pierre | E15: Tragin SAS (Tragin et Associés) | F15: Pont-l'Évêque (14130) | G15: Normandie | H15: Entreprise familiale de pose fondée en 1956, avec 21 poseurs, qui pose marbres, pierres naturelles et terrasses sur plots pour des architectes et promoteurs de la Côte Fleurie : elle pourrait acheter MINYALA par lots (usage à valider avec lui : finition, gel, glissance, humidité). | I15: www.tragin-sa.com | J15: 02 31 88 25 78 | K15: Voir | L15: Contacté | M15: 12/10/2026 | N15: Vérifier la réponse dans la boîte Hotmail d'envoi ; une seule relance (~19/10) si silence | O15: E-mail de prospection (tarif pro) du 12/10/2026 à 15:00 (copie reçue en SPAM). | P15: 3e liste (12/10) | Q15: tragin-sa@wanadoo.fr
A16: 15 | B16: Pro France | C16: 1 | D16: Showroom carrelage | E16: Batimantes (showrooms carrelage et salle de bains) | F16: Colombes (92700) | G16: Île-de-France | H16: Distributeur avec plusieurs showrooms carrelage et salle de bains dans le 92, le 78 et le 95 : il pourrait ajouter MINYALA à son offre pour les sols intérieurs et les salles de bains. | I16: www.batimantes.fr | J16: 01 47 82 82 36 | K16: Voir | L16: Contacté | M16: 12/10/2026 | N16: Vérifier la réponse dans la boîte Hotmail d'envoi ; une seule relance (~19/10) si silence | O16: E-mail de prospection (tarif pro) du 12/10/2026 à 15:03 (copie reçue en SPAM). | P16: 3e liste (12/10) | Q16: colombes.expo@batimantes.fr
A17: 16 | B17: Pro France | C17: 1 | D17: Pisciniste | E17: Belles Piscines (concessionnaire Mondial Piscine) | F17: Coignières (78310) | G17: Île-de-France | H17: Son showroom vend déjà carrelages extérieurs, margelles et dallages : MINYALA pourrait compléter sa gamme de plages de piscine dans les Yvelines (usage à valider avec lui : finition, gel, glissance, humidité). | I17: coignieres.mondial-piscine.eu | J17: 01 34 89 64 10 | K17: Voir | L17: À contacter | O17: [13/10] Lien « Envoyer un e-mail » de la page Notre agence (Coignières). | P17: 2e liste (12/10) | Q17: accueil@belles-piscines.com
A18: 17 | B18: Pro France | C18: 1 | D18: Négoce / revendeur | E18: BigMat Aubert Matériaux | F18: Mareil-sur-Mauldre (78124) | G18: Île-de-France | H18: Négoce BigMat des Yvelines doté de showrooms carrelage et aménagement extérieur, il pourrait stocker MINYALA pour ses artisans et ses clients particuliers. | J18: 01 30 90 71 75 | K18: Voir | L18: À contacter | P18: 3e liste (12/10)
A19: 18 | B19: Pro France | C19: 1 | D19: Showroom carrelage | E19: Carrelage Design 95 | F19: Saint-Ouen-l'Aumône (95310) | G19: Île-de-France | H19: Ce cash & carry du Val-d'Oise vend déjà pierre naturelle et travertin sur stock, donc il peut racheter un lot de MINYALA et le revendre aux particuliers et aux carreleurs. | I19: www.carrelage-design-95.fr | J19: 07 83 34 77 88 | K19: Voir | L19: À rapprocher (export Hotmail) | N19: Rapprocher l'export Hotmail (~180 messages / 95 destinataires) avant tout envoi ; ensuite, boîte Gmail uniquement | O19: [13/10] E-mail affiché sur le site (pied de page, contact, mentions légales). | [13/10] Tentative depuis Hotmail rejetée EN SORTIE (5.7.520 : contenu classé spam par Microsoft) — message non remis ; l'adresse n'est pas forcément invalide. Prochain contact depuis la boîte Gmail, nouveau modèle, jamais depuis Hotmail. | [13/10 soir] L'export Hotmail recense des tentatives ultérieures vers cette adresse (issue non confirmée) : ne plus compter « jamais contacté » ; statut à arrêter au rapprochement de l'export. | P19: 2e liste (12/10) | Q19: contact@carrelage-design-95.fr
A20: 19 | B20: Pro France | C20: 1 | D20: Négoce / revendeur | E20: Carrelage Roger Herblay | F20: Herblay-sur-Seine (95220) | G20: Île-de-France | H20: Ce négociant indépendant vend déjà de la pierre naturelle et du carrelage de terrasse dans son showroom d'Herblay : il pourrait référencer MINYALA. | I20: www.carrelage-roger.com | J20: 01 39 31 93 10 | K20: Voir | L20: À rapprocher (export Hotmail) | N20: Rapprocher l'export Hotmail (~180 messages / 95 destinataires) avant tout envoi ; ensuite, boîte Gmail uniquement | O20: [13/10] E-mail des mentions légales (attention : domaine inversé roger-carrelage.com, tel qu'affiché par le site). | [13/10] Tentative Hotmail du 12/10 vers broger@roger-carrelage.com (nominative) rejetée en sortie (5.7.520). Utiliser l'adresse générique, depuis Gmail. | [13/10 soir] L'export Hotmail recense des tentatives ultérieures vers cette adresse (issue non confirmée) : ne plus compter « jamais contacté » ; statut à arrêter au rapprochement de l'export. | P20: 2e liste (12/10) | Q20: contact@roger-carrelage.com
A21: 20 | B21: Pro France | C21: 1 | D21: Négoce / revendeur | E21: Carrelages Pedrazzini | F21: Voisenon (77950) | G21: Île-de-France | H21: Vend de la pierre naturelle, showroom et stock important : peut reprendre un gros lot. | K21: Voir | L21: À contacter | P21: 1re liste (08/10)
A22: 21 | B22: Pro France | C22: 1 | D22: Showroom carrelage | E22: Ceramico | F22: Sarcelles (95200) | G22: Île-de-France | H22: Déstockeur de carrelage au gros stock qui vend déjà marbre, travertin et dallage en pierre naturelle, il est un acheteur naturel pour un lot de MINYALA disponible au tarif professionnel (sur devis). | I22: www.ceramico.fr | J22: 01 86 04 82 15 | K22: Voir | L22: À contacter | P22: 3e liste (12/10)
A23: 22 | B23: Pro France | C23: 1 | D23: Marbrerie | E23: Décomarbre | F23: Bry-sur-Marne (94360) | G23: Île-de-France | H23: Marbrerie avec showroom qui garde un stock permanent de dallages et travaille déjà le travertin, elle pourrait ajouter MINYALA en 30×60 à son stock de dallages. | I23: www.decomarbre.fr | J23: 01 48 81 28 49 | K23: Voir | L23: À contacter | N23: Prochain contact depuis la boîte Gmail (pas Hotmail), après fusion du suivi | O23: [13/10] Tentative depuis Hotmail rejetée EN SORTIE (5.7.520 : contenu classé spam par Microsoft) — message non remis ; l'adresse n'est pas forcément invalide. Prochain contact depuis la boîte Gmail, nouveau modèle, jamais depuis Hotmail. | P23: 3e liste (12/10) | Q23: decomarbre@decomarbre94.fr
A24: 23 | B24: Pro France | C24: 1 | D24: Carreleur / poseur pierre | E24: FLIPO | F24: Pantin (93500) | G24: Île-de-France | H24: Entreprise de Pantin dont le pôle carrelage et marbrerie pose pierre et marbre dans tous formats, y compris en espaces balnéo et pour l'hôtellerie : elle pourrait proposer MINYALA sur ses chantiers. | I24: flipo.fr | J24: 01 48 91 20 50 | K24: Voir | L24: Contacté | M24: 12/10/2026 | N24: Vérifier la réponse dans la boîte Hotmail d'envoi ; une seule relance (~19/10) si silence | O24: E-mail de prospection (tarif pro) du 12/10/2026 à 15:04 (copie reçue en SPAM). | P24: 3e liste (12/10) | Q24: flipo@flipo.fr
A25: 24 | B25: Pro France | C25: 1 | D25: Négoce / revendeur | E25: Gedimat Aux Docks de Clamart (Concept Store Sols & Bains) | F25: Clamart (92140) | G25: Île-de-France | H25: Négoce Gedimat avec rayon pavés et dallages et un showroom Sols & Bains, qui pourrait référencer MINYALA en dallage extérieur comme en sol intérieur. | I25: www.gedimat.fr/2264-magasin-gedimat-aux-docks-de-clamart-clamart.htm | J25: 01 46 01 52 20 | K25: Voir | L25: Contacté | M25: 12/10/2026 | N25: Vérifier la réponse dans la boîte Hotmail d'envoi ; une seule relance (~19/10) si silence | O25: E-mail de prospection (tarif pro) du 12/10/2026 à 15:03 (copie reçue en SPAM). | P25: 3e liste (12/10) | Q25: expo@docksclamart.fr
A26: 25 | B26: Pro France | C26: 1 | D26: Négoce / revendeur | E26: Gedimat Sefor Houilles | F26: Houilles (78800) | G26: Île-de-France | H26: Grand négoce de 25 000 m² avec exposition revêtements, sols et terrasses et un responsable carrelage et aménagement extérieur : il pourrait acheter un lot de MINYALA pour ses clients pros et particuliers. | I26: www.gedimat.fr/2034-magasin-gedimat-sefor-houilles.htm | J26: 01 39 57 10 10 | K26: Voir | L26: Contacté | M26: 12/10/2026 | N26: Vérifier la réponse dans la boîte Hotmail d'envoi ; une seule relance (~19/10) si silence | O26: E-mail de prospection (tarif pro) du 12/10/2026 à 15:03 (copie reçue en SPAM). | P26: 3e liste (12/10) | Q26: guillaume.lallet@gedimat.fr
A27: 26 | B27: Pro France | C27: 1 | D27: Showroom carrelage | E27: Kap Carrelage Domont | F27: Domont (95330) | G27: Île-de-France | H27: Showroom carrelage du Val-d'Oise qui vend aux particuliers et aux pros, pour terrasses et piscines, et fait du déstockage : il pourrait acheter MINYALA en lot pour le revendre (usage à valider avec lui : finition, gel, glissance, humidité). | I27: kap-carrelage.store | J27: 01 30 18 50 14 | K27: Voir | L27: Contacté | M27: 12/10/2026 | N27: Vérifier la réponse dans la boîte Hotmail d'envoi ; une seule relance (~19/10) si silence | O27: E-mail de prospection (tarif pro) du 12/10/2026 à 15:04 (copie reçue en SPAM). | P27: 3e liste (12/10) | Q27: contact@kap-carrelage.store
A28: 27 | B28: Pro France | C28: 1 | D28: Négoce / revendeur | E28: La Halle aux Pierres | F28: Gometz-le-Châtel (91940) | G28: Île-de-France | H28: Négoce de matériaux de construction. | K28: Voir | L28: À contacter | N28: Prochain contact depuis la boîte Gmail (pas Hotmail), après fusion du suivi | O28: Rapprochement du 13/10 (autre assistant) : dernier envoi rejeté (échec de remise) — à confirmer, puis trouver une autre adresse. | [13/10] Tentative depuis Hotmail rejetée EN SORTIE (5.7.520 : contenu classé spam par Microsoft) — message non remis ; l'adresse n'est pas forcément invalide. Prochain contact depuis la boîte Gmail, nouveau modèle, jamais depuis Hotmail. | P28: 1re liste (08/10) | Q28: lahalleauxpierres@orange.fr
A29: 28 | B29: Pro France | C29: 1 | D29: Négoce / revendeur | E29: Le Holloco | F29: Herblay-sur-Seine (95220) | G29: Île-de-France | H29: Négoce du Val-d'Oise avec trois agences, une offre de dalles et pavés pour l'extérieur et des espaces d'exposition carrelage : il pourrait référencer MINYALA. | I29: leholloco.com | J29: 01 34 50 95 00 | K29: Voir | L29: Contacté | M29: 12/10/2026 | N29: Vérifier la réponse dans la boîte Hotmail d'envoi ; une seule relance (~19/10) si silence | O29: E-mail de prospection (tarif pro) du 12/10/2026 à 15:00 (copie reçue en SPAM). | P29: 3e liste (12/10) | Q29: materiaux@leholloco.fr
A30: 29 | B30: Pro France | C30: 1 | D30: Paysagiste | E30: Le Monde des Jardins | F30: Deuil-la-Barre (95170) | G30: Île-de-France | H30: Ce paysagiste du Val-d'Oise fait de la pierre naturelle son matériau de prédilection et utilise déjà un calcaire à patine dorée : MINYALA, de teinte crème, peut compléter sa gamme pour terrasses et dallages. | I30: lemondedesjardins.fr | J30: 01 34 28 80 46 | K30: Voir | L30: À rapprocher (export Hotmail) | N30: Rapprocher l'export Hotmail (~180 messages / 95 destinataires) avant tout envoi ; ensuite, boîte Gmail uniquement | O30: [13/10] Page contact (domaine .com alors que le site est en .fr : tel qu'affiché). | [13/10] Tentative depuis Hotmail rejetée EN SORTIE (5.7.520 : contenu classé spam par Microsoft) — message non remis ; l'adresse n'est pas forcément invalide. Prochain contact depuis la boîte Gmail, nouveau modèle, jamais depuis Hotmail. | [13/10 soir] L'export Hotmail recense des tentatives ultérieures vers cette adresse (issue non confirmée) : ne plus compter « jamais contacté » ; statut à arrêter au rapprochement de l'export. | P30: 2e liste (12/10) | Q30: contact@lemondedesjardins.com
A31: 30 | B31: Pro France | C31: 1 | D31: Négoce / revendeur | E31: MCA Matériaux Cuisines Aménagements (France Matériaux) | F31: Achères (78260) | G31: Île-de-France | H31: Négoce du réseau France Matériaux avec showroom carrelage et une offre aménagement extérieur : il pourrait proposer MINYALA à ses clients pros et particuliers. | I31: www.mca-materiaux.com | J31: 01 30 06 00 07 | K31: Voir | L31: Contacté | M31: 12/10/2026 | N31: Vérifier la réponse dans la boîte Hotmail d'envoi ; une seule relance (~19/10) si silence | O31: E-mail de prospection (tarif pro) du 12/10/2026 à 15:03 (copie reçue en INBOX). | P31: 3e liste (12/10) | Q31: contact@mca-materiaux.net
A32: 31 | B32: Pro France | C32: 1 | D32: Marbrerie | E32: MDY - Marbrerie des Yvelines | F32: Versailles (78000) | G32: Île-de-France | H32: Cette marbrerie de Versailles, qui a aussi un showroom à Pont-l'Évêque, vend déjà du dallage en pierre naturelle pour terrasses et abords de piscine : MINYALA peut entrer dans sa gamme (usage à valider avec lui : finition, gel, glissance, humidité). | I32: www.mdy-france.com | J32: 01 39 24 17 17 | K32: Voir | L32: Contacté | M32: 12/10/2026 | N32: Vérifier la réponse dans la boîte Hotmail d'envoi ; une seule relance (~19/10) si silence | O32: E-mail de prospection (tarif pro) du 12/10/2026 à 15:01 (copie reçue en SPAM). | P32: 2e liste (12/10) | Q32: contact@mdy-france.com
A33: 32 | B33: Pro France | C33: 1 | D33: Marbrerie | E33: Marbrier Pierre Taille (MPT) | F33: Chilly-Mazarin (91380) | G33: Île-de-France | H33: Fournisseur-poseur de pierres naturelles en sols et façades, avec des références hôtelières : il pourrait acheter MINYALA par lots pour ses dallages. | I33: www.mpt-marbrier.fr | J33: 01 69 74 12 80 | K33: Voir | L33: À contacter | P33: 3e liste (12/10)
A34: 33 | B34: Pro France | C34: 1 | D34: Négoce / revendeur | E34: Natou Pierre | F34: Paris 17e (75017) | G34: Île-de-France | H34: Fourniture et pose de pierre. | K34: Voir | L34: À contacter | N34: Prochain contact depuis la boîte Gmail (pas Hotmail), après fusion du suivi | O34: Rapprochement du 13/10 (autre assistant) : dernier envoi rejeté (échec de remise) — à confirmer, puis trouver une autre adresse. | [13/10] Tentative depuis Hotmail rejetée EN SORTIE (5.7.520 : contenu classé spam par Microsoft) — message non remis ; l'adresse n'est pas forcément invalide. Prochain contact depuis la boîte Gmail, nouveau modèle, jamais depuis Hotmail. | P34: 1re liste (08/10) | Q34: contact@natoupierre.fr
A35: 34 | B35: Pro France | C35: 1 | D35: Marbrerie | E35: PMC Marbrerie (Pierres Marbreries Carrelages) | F35: Montigny-lès-Cormeilles (95370) | G35: Île-de-France | H35: Cette marbrerie du Val-d'Oise vend déjà dallages et pierres naturelles depuis plus de 30 ans, donc un calcaire en stock au tarif professionnel (sur devis) peut compléter son offre de sols. | I35: www.pmc-marbrerie.com | J35: 01 39 89 79 30 | K35: Voir | L35: Contacté | M35: 12/10/2026 | N35: Vérifier la réponse dans la boîte Hotmail d'envoi ; une seule relance (~19/10) si silence | O35: E-mail de prospection (tarif pro) du 12/10/2026 à 14:58 (copie reçue en INBOX). | P35: 2e liste (12/10) | Q35: contact@pmc-marbrerie.com
A36: 35 | B36: Pro France | C36: 1 | D36: Négoce / revendeur | E36: Paco | F36: Courcouronnes (91080) | G36: Île-de-France | H36: Marbrerie et vente de carrelage et de dallage. | K36: Voir | L36: À contacter | N36: Prochain contact depuis la boîte Gmail (pas Hotmail), après fusion du suivi | O36: Rapprochement du 13/10 (autre assistant) : dernier envoi rejeté (échec de remise) — à confirmer, puis trouver une autre adresse. | [13/10] Tentative depuis Hotmail rejetée EN SORTIE (5.7.520 : contenu classé spam par Microsoft) — message non remis ; l'adresse n'est pas forcément invalide. Prochain contact depuis la boîte Gmail, nouveau modèle, jamais depuis Hotmail. | P36: 1re liste (08/10) | Q36: sarlpaco@wanadoo.fr
A37: 36 | B37: Pro France | C37: 1 | D37: Showroom carrelage | E37: Palatino | F37: Nanterre (92000) | G37: Île-de-France | H37: Négociant en pierre naturelle à Nanterre, tout près de Gennevilliers, avec 1 500 m² de stockage, il peut racheter un lot complet de MINYALA pour sa clientèle. | I37: www.palatino.fr | J37: 01 42 04 90 30 | K37: Voir | L37: À rapprocher (export Hotmail) | N37: Rapprocher l'export Hotmail (~180 messages / 95 destinataires) avant tout envoi ; ensuite, boîte Gmail uniquement | O37: [13/10] Page contact du site officiel (showroom Nanterre). | [13/10] Tentative depuis Hotmail rejetée EN SORTIE (5.7.520 : contenu classé spam par Microsoft) — message non remis ; l'adresse n'est pas forcément invalide. Prochain contact depuis la boîte Gmail, nouveau modèle, jamais depuis Hotmail. | [13/10 soir] L'export Hotmail recense des tentatives ultérieures vers cette adresse (issue non confirmée) : ne plus compter « jamais contacté » ; statut à arrêter au rapprochement de l'export. | P37: 2e liste (12/10) | Q37: info@palatino.fr
A38: 37 | B38: Pro France | C38: 1 | D38: Showroom carrelage | E38: Parquet-Carrelage.com (showroom Paris 17e) | F38: Paris (75017) | G38: Île-de-France | H38: Ce distributeur parisien de sols, avec un gros stock et plusieurs showrooms, référence déjà pierre naturelle et travertin : un débouché possible en volume pour MINYALA. | I38: www.parquet-carrelage.com | J38: 01 48 82 58 58 | K38: Voir | L38: Contacté | M38: 12/10/2026 | N38: Vérifier la réponse dans la boîte Hotmail d'envoi ; une seule relance (~19/10) si silence | O38: E-mail de prospection (tarif pro) du 12/10/2026 à 15:01 (copie reçue en INBOX). | P38: 2e liste (12/10) | Q38: contact@parquet-carrelage.com
A39: 38 | B39: Pro France | C39: 1 | D39: Négoce / revendeur | E39: Pierlux | F39: Auvers-Saint-Georges (91580) | G39: Île-de-France | H39: Négociant en pierres naturelles et matériaux d'aménagement extérieur qui fournit artisans, paysagistes et architectes, il pourrait référencer MINYALA dans sa gamme de dallages. | I39: www.pierluxpierrenaturelle.fr | J39: 01 64 92 06 33 | K39: Voir | L39: À contacter | O39: [13/10] Page contact du site officiel. | P39: 3e liste (12/10) | Q39: pierluxfrance@orange.fr
A40: 39 | B40: Pro France | C40: 1 | D40: Jardinerie / matériaux paysage | E40: Pierres Nat' | F40: Linas (91310) | G40: Île-de-France | H40: Revendeur de pierre naturelle depuis 1994 avec un showroom extérieur de 2 500 m² et une clientèle de professionnels et de particuliers, il pourrait revendre MINYALA en dallage de terrasse et d'allée. | I40: pierres-nat.com | J40: 01 69 80 68 15 | K40: Voir | L40: À contacter | P40: 3e liste (12/10)
...

Sheet Où trouver des particuliers
A1: Canal | B1: Type | C1: Qui on y touche | D1: Dates / zone | E1: Ce qu'il faut faire | F1: Coût | G1: Lien | H1: Fait le
A2: Leboncoin — compte Pro | B2: Annonces | C2: Particuliers et petits artisans qui cherchent de la pierre près de chez eux | D2: Une annonce localisée à Gennevilliers ; Vernon seulement quand l'adresse, les horaires et le stock y sont | E2: Compte Pro obligatoire. Une seule annonce au départ : lot de 25 m² à 875 €, vraies photos sans texte, IDU de la filière REP, pas de lien ni de paiement en ligne Leboncoin pour l'instant. Texte, photos et liste de contrôle : leboncoin.md. | F2: Compte Pro gratuit ; 50 dépôts offerts au total en Maison & Jardin ; 12 % de commission si paiement en ligne | G2: Ouvrir
A3: Fiche Google (Google Business Profile) | B3: Fiche | C3: Personnes qui cherchent « pierre naturelle » ou « dallage » près de Gennevilliers | D3: Recherche locale | E3: Créer une fiche par point de retrait (Gennevilliers, puis Vernon dès que l'adresse est connue) : catégorie fournisseur de pierre, retrait sur rendez-vous, photos réelles, lien vers la fiche MINYALA. Demander un avis à chaque client. | F3: Gratuit | G3: Ouvrir
A4: Houzz — profil pro « Pierres et plans de travail » | B4: Fiche | C4: Particuliers en projet et architectes qui cherchent un fournisseur | D4: Recherche par ville (rayon 10 à 100 km) | E4: Créer un profil pro situé à Gennevilliers (zone d'intervention incluant l'Eure / Vernon) avec photos de MINYALA posé, prix au m² et minimum de commande. Demander des avis clients. | F4: Inscription gratuite (options payantes à vérifier) | G4: Ouvrir
A5: PagesJaunes — fiche professionnelle | B5: Fiche | C5: Recherches par ville et par métier | D5: France | E5: Créer ou revendiquer la fiche Pierre d'Égypte, rubriques pierre naturelle et carrelage, avec photos et lien vers le site. | F5: Fiche gratuite (options payantes) | G5: Ouvrir
A6: Vivastreet — Bricolage, jardinage | B6: Annonces | C6: Particuliers | D6: Annonce localisée à Gennevilliers, et une 2e à Vernon (27) dès que l'adresse est connue | E6: Lire les règles de l'Espace Pro, puis publier une annonce pro identifiée avec photos et prix au m². | F6: Certaines catégories payantes (à vérifier) | G6: Ouvrir
A7: Facebook — Page entreprise (pas Marketplace) | B7: Réseau social | C7: Particuliers d'Île-de-France et de Normandie | D7: Local | E7: Marketplace est réservé aux ventes entre particuliers et Meta peut bloquer les vendeurs pros. Créer une Page Pierre d'Égypte et utiliser les publicités Meta à la place. Ne jamais publier en se faisant passer pour un particulier. | F7: Page gratuite | G7: Ouvrir
A8: Groupes Facebook locaux (à chercher vous-même) | B8: Réseau social | C8: Propriétaires qui préparent des travaux | D8: 92, 95, 78, 93, Normandie | E8: Voir l'onglet Groupes Facebook (22 groupes repérés). Pour d'autres groupes locaux, dans Facebook, cherchez « travaux maison 92 », « piscine Île-de-France », « jardin Normandie », « bons plans matériaux », « déstockage matériaux ». Lisez le règlement : ne publiez que là où les pros sont autorisés, idéalement avec l'accord des administrateurs. | F8: Gratuit
A9: ForumConstruire — Terrasse « en dur » | B9: Forum | C9: Forum de construction très fréquenté par des propriétaires de maison. | D9: France entière | E9: Créer un compte clairement identifié comme professionnel et répondre aux questions sur la pierre calcaire (pose, joints, entretien), sans publicité. Avec l'accord d'un client, publier un récit de chantier avec photos. | F9: Gratuit | G9: Ouvrir
A10: ForumConstruire — Allées et chemins | B10: Forum | C10: Forum de construction très fréquenté par des propriétaires de maison. | D10: France entière | E10: Répondre aux questions sur les allées en pierre (pose sur lit de mortier ou sur dalle, joints). Le format 30×60 convient aux chemins de jardin. Pas de lien commercial dans les messages. | F10: Gratuit | G10: Ouvrir
A11: ForumConstruire — Carrelage | B11: Forum | C11: Forum de construction très fréquenté par des propriétaires de maison. | D11: France entière | E11: Intervenir sur les sujets pierre naturelle et travertin pour les sols intérieurs, en conseil technique. | F11: Gratuit | G11: Ouvrir
A12: ForumConstruire — Rénovation et extension | B12: Forum | C12: Forum de construction très fréquenté par des propriétaires de maison. | D12: France entière | E12: Répondre aux questions de remplacement de sols ou de terrasse. Laisser les membres demander vos coordonnées. | F12: Gratuit | G12: Ouvrir
A13: ForumPiscine — Terrasse (autour de la piscine) | B13: Forum | C13: Propriétaires de piscine qui choisissent leur plage | D13: France entière | E13: Répondre sur le choix, la pose et l'entretien d'une plage en pierre. La charte pro interdit toute publicité, signature commerciale ou lien vers le site. | F13: Gratuit | G13: Ouvrir
A14: ForumPiscine — Piscine maçonnée | B14: Forum | C14: Propriétaires en cours de construction, avant le choix de la plage | D14: France entière | E14: Repérer les projets au stade du chantier et apporter des réponses techniques sur la pierre autour du bassin, sans promotion. | F14: Gratuit | G14: Ouvrir
A15: Houzz — Discussions (paysage, jardin, piscine, rénovation) | B15: Forum | C15: Particuliers en projet | D15: France entière | E15: Répondre avec le profil pro Houzz et des photos de réalisations. Les réponses renvoient vers votre profil. | F15: Gratuit | G15: Ouvrir
A16: ForumConstruire — avis sur les boutiques | B16: Avis | C16: Futurs acheteurs qui vérifient un vendeur | D16: France entière | E16: Inviter chaque client, sans tri, à laisser un avis après le retrait ou la livraison. Ne jamais rédiger de faux avis ni offrir de contrepartie (sanctionné). | F16: Gratuit | G16: Ouvrir
A17: Foire de Rouen 2027 | B17: Foire | C17: Grand public normand en projet maison et jardin | D17: 27 mars – 4 avril 2027, Parc des Expositions de Rouen (Le Grand-Quevilly) | E17: Demander le dossier exposant (univers Maison & Jardin). Bon moment pour lancer la saison terrasse en Normandie. | F17: À vérifier | G17: Ouvrir
A18: Foire de Paris 2027 | B18: Foire | C18: Grand public francilien en projet maison | D18: 30 avril – 10 mai 2027, Paris (lieu à confirmer, habituellement Porte de Versailles) | E18: Visiter pour repérer exposants terrasse et piscine et poseurs partenaires, et chiffrer un stand pour 2028. Sur un stand, ne collecter des contacts qu'avec consentement explicite. | F18: À vérifier | G18: Ouvrir
A19: Foire internationale de Caen | B19: Foire | C19: Grand public du Calvados et de la Côte Fleurie | D19: Dates 2027 non publiées (2026 : 18–27 septembre, Parc des Expositions de Caen) | E19: Surveiller les dates 2027 et demander un dossier exposant secteur Habitat & Jardin. | F19: À vérifier | G19: Ouvrir
A20: Salon de la copropriété et de l'habitat | B20: Salon | C20: Syndics, conseils syndicaux et copropriétaires | D20: 4–5 novembre 2026, Paris | E20: Y aller en visiteur pour présenter MINYALA pour des halls et des cours de copropriété. | F20: À vérifier | G20: Ouvrir
... A41: InfoNormandie (site d'actualité locale) | B41: Presse | C41: Lecteurs de Rouen, Le Havre, Dieppe, Évreux, Vernon | D41: Seine-Maritime, Eure | E41: Proposer un sujet (chantier réalisé en Normandie) via la page de soumission et demander s'il existe des formats publicitaires. | F41: Aucune offre publiée | G41: Ouvrir
A42: Idées de ciblage
A43: • Saison : préparer en janvier-février (fiche Google, Houzz, Pinterest), pousser de mars à juin pour les terrasses et piscines, puis viser sols intérieurs et cuisines de septembre à novembre.
A44: • Piscines : visuels de plages en MINYALA diffusés d'avril à juin, avant l'ouverture des bassins.
A45: • Une terrasse familiale fait souvent plus de 25 m² : le minimum de commande n'est pas un frein, dites-le dans les annonces.
A46: • Reciblage des visiteurs du site seulement avec un bandeau cookies conforme (voir onglet Règles).
A47: • Collecter des contacts avec une case de consentement non pré-cochée (formulaire « recevoir les prix / le guide de pose », foires). Sans ce consentement, pas d'e-mail, de SMS ni d'appel à un particulier.
A48: • À décider : échantillons à retirer à Gennevilliers ou Vernon. Le tarif pro existe désormais, par devis et facture uniquement.

Sheet Plateformes pros
A1: Canal | B1: Pour qui | C1: Dates / lieu | D1: Ce qu'il faut faire | E1: Lien
A2: Backacia | B2: Pros du bâtiment (surplus, fins de série) | C2: Entrepôt Ivry-sur-Seine | D2: Demander s'ils acceptent un lot de dallage en pierre et à quelles conditions. | E2: Ouvrir
A3: Cycle Up | B3: Architectes, constructeurs, négoces | C3: Paris | D3: Marketplace des surplus et stocks invendus du négoce. Demander s'ils prennent la pierre. | E3: Ouvrir
A4: BOAMP — alertes marchés publics | B4: Communes, Paris La Défense, bailleurs | C4: Filtrer 75, 92, 95, 76, 14, 27 | D4: Créer des alertes « pierre naturelle » et « dallage ». Contacter les entreprises qui gagnent ces marchés pour les approvisionner. | E4: Ouvrir
A5: Marché public : piscine de Chatou (78) | B5: Entreprises qui feront les travaux | C5: Avis publié le 20/01/2026, travaux annoncés sept. 2026 – juil. 2027 | D5: Suivre l'avis (procédure annoncée comme relancée) et contacter les entreprises retenues pour les plages et abords. | E5: Ouvrir
A6: EquipHotel 2026 | B6: Architectes et agenceurs d'hôtels et restaurants | C6: 2–5 novembre 2026, Paris Expo Porte de Versailles | D6: Visiter pour rencontrer des prescripteurs de sols et terrasses pour l'hôtellerie. | E6: Ouvrir
A7: Piscine Global Europe 2026 | B7: Piscinistes et réseaux (Mondial Piscine, Magiline, L'Esprit Piscine…) | C7: 17–20 novembre 2026, Eurexpo Lyon | D7: Visiter avec photos et prix pour rencontrer les réseaux de piscinistes dont plusieurs agences sont dans l'onglet Prospects. | E7: Ouvrir
A8: Salon des Maires et des Collectivités 2026 | B8: Services voirie et espaces publics | C8: 24–26 novembre 2026, Paris Expo Porte de Versailles | D8: Repérer les futurs appels d'offres de dallage. Ne proposer MINYALA pour l'espace public qu'avec des essais (glissance, gel, flexion) adaptés à un calcaire de 2 cm. | E8: Ouvrir
A9: Paysalia + Rocalia 2027 | B9: Paysagistes, marbriers, négociants (Rocalia = salon de la pierre) | C9: 30 nov. – 2 déc. 2027, Eurexpo Lyon (dates Rocalia à confirmer) | D9: Visiter ou exposer pour rencontrer les acheteurs de pierre en volume. | E9: Ouvrir
A10: 118712 — catégorie pierres naturelles | B10: Pros qui cherchent un fournisseur | C10: Île-de-France | D10: Vérifier que Pierre d'Égypte y figure, avec retrait sur rendez-vous et lien vers le site. | E10: Ouvrir
A11: Les Thermalies 2027 | B11: Exploitants de spas et de thalassos (dont Côte Fleurie) | C11: 21–24 janvier 2027, Carrousel du Louvre, Paris | D11: Repérer les spas qui préparent une rénovation (pavillons « Luxury Spa » et « Innovation Design »). | E11: Ouvrir
A12: Trouville-sur-Mer — réaménagement de la rue des Bains | B12: Ville, entreprises de voirie, restaurants de la rue | C12: Réseaux jusqu'au 3 avril 2027, puis nouveau revêtement (date à confirmer) | D12: Suivre le futur marché de revêtement et contacter les restaurants dont les terrasses seront refaites. | E12: Ouvrir
... A21: ChatGPT (via Shopify) | B21: Acheteurs qui demandent conseil à ChatGPT | C21: Non disponible (13/10/2026) : réservé aux boutiques qui vendent aux États-Unis | D21: Pas de canal de vente possible pour l'instant. Visibilité gratuite : les pages du site peuvent être citées par la recherche de ChatGPT. D'ici là : passer les produits « Acompte » en « Non répertorié », remplir les CGV et la politique de remboursement, ajouter des photos réelles. | E21: Ouvrir
A22: E-mail / téléphone aux pros | B22: Les entreprises de l'onglet Prospects | C22: — | D22: Message prêt dans le kit de vente (section 4). Autorisé si le message concerne leur métier, avec possibilité de refuser (voir Règles). 10 contacts par semaine, relance après 7 jours.

Sheet Groupes Facebook
A1: Groupe | B1: Zone | C1: Type | D1: Membres (source, date) | E1: Ce qu'il faut faire | F1: Lien | G1: Source | H1: Demande admin le | I1: Réponse | J1: Publié le
A2: VendezVosMateriaux.fr - Vente de matériaux et outils de chantier | B2: France | C2: Groupe public matériaux (pros et particuliers) | D2: 46,5 K (vu le 12/10/2026) | E2: Groupe mixte pros + particuliers. Annonce au tarif pro en attente depuis le 12/10/2026 : demander à l'admin de la modifier ou la retirer AVANT validation, puis republier au prix public 35 €/m² pierre seule avec « Professionnels et gros volumes : tarif sur demande (devis et facture) ». Lien du groupe à ajouter. | G2: Capture du 12/10 | H2: 12/10/2026 | I2: En attente
A3: LES PRO DU BÂTIMENT | B3: France | C3: Groupe pro | D3: Non relevé | E3: Annonce déjà présente (doublon évité le 12/10/2026). Vérifier : groupe privé et réservé aux pros ? Quel prix affiche l'annonce ? Si le groupe est ouvert aux particuliers, modifier l'annonce au prix public 35 €/m² pierre seule + « Pros : tarif sur demande ». Sinon, répondre seulement. Lien du groupe à ajouter. | G3: Capture du 12/10 | J3: avant le 12/10/2026
A4: Tu sais que tu viens de Rouen quand… | B4: Rouen (76) | C4: Communauté de ville | D4: 45 000+ (Tendance Ouest, 2018) ; ~48 000 (ici.fr, 2019) | E4: Prioritaire Normandie. Rejoindre avec la Page, lire le règlement, écrire à l'admin avant de publier une seule annonce. Tous les messages y sont validés par l'admin. | F4: Ouvrir | G4: Voir
A5: Réseau « Tu sais que tu viens de… » (≈50 groupes) | B5: Seine-Maritime, Eure, Caen, Lisieux… | C5: Réseau de groupes | D5: ~500 000 abonnés au total (ici.fr, 2019) | E5: Plutôt qu'un groupe à la fois : demander à l'administrateur du réseau s'il existe une offre commerçant ou un partenariat payant (« Tu sais que tu viens de gagner » en 2019, à vérifier). | G5: Voir
A6: Tu sais que tu viens de… Caen | B6: Caen (14) | C6: Communauté de ville | D6: Non publié | E6: Rejoindre avec la Page, lire le règlement, écrire à l'admin avant de publier une seule annonce. | F6: Ouvrir | G6: Voir
A7: Tu sais que tu viens de… Le Havre | B7: Le Havre (76) | C7: Communauté de ville | D7: Non publié | E7: Rejoindre avec la Page, lire le règlement, écrire à l'admin avant de publier une seule annonce. | F7: Ouvrir | G7: Voir
A8: Tu sais que tu viens de… Évreux | B8: Évreux (27) | C8: Communauté de ville | D8: 29 000+ (ici.fr, 2016–2019 ; article de 2016 indisponible) | E8: Rejoindre avec la Page, lire le règlement, écrire à l'admin avant de publier une seule annonce. (Lien relevé dans un article ici.fr de 2016 aujourd'hui indisponible ; source jointe : article ici.fr de 2019 sur le même réseau.) | F8: Ouvrir | G8: Voir
A9: Tu sais que tu viens de… Louviers | B9: Louviers (27) | C9: Communauté de ville | D9: Non publié | E9: Rejoindre avec la Page, lire le règlement, écrire à l'admin avant de publier une seule annonce. | F9: Ouvrir | G9: Voir
A10: Tu sais que tu viens de… Bernay | B10: Bernay (27) | C10: Communauté de ville | D10: Non publié | E10: Rejoindre avec la Page, lire le règlement, écrire à l'admin avant de publier une seule annonce. Beaucoup de maisons avec jardin. | F10: Ouvrir | G10: Voir
A11: Tu sais que tu viens de… Le Neubourg | B11: Le Neubourg (27) | C11: Communauté de ville | D11: Non publié | E11: Rejoindre avec la Page, lire le règlement, écrire à l'admin avant de publier une seule annonce. | F11: Ouvrir | G11: Voir
A12: Tu sais que tu viens de… Dieppe | B12: Dieppe (76) | C12: Communauté de ville | D12: Non publié | E12: Vérifier qu'il est actif (source 2016). Rejoindre avec la Page, lire le règlement, écrire à l'admin avant de publier une seule annonce. (Lien relevé dans un article ici.fr de 2016 aujourd'hui indisponible ; source jointe : article ici.fr de 2019 sur le même réseau.) | F12: Ouvrir | G12: Voir
A13: Tu sais que tu viens de… Fécamp | B13: Fécamp (76) | C13: Communauté de ville | D13: Non publié | E13: Résidences secondaires du littoral. Rejoindre avec la Page, lire le règlement, écrire à l'admin avant de publier une seule annonce. (Lien relevé dans un article ici.fr de 2016 aujourd'hui indisponible ; source jointe : article ici.fr de 2019 sur le même réseau.) | F13: Ouvrir | G13: Voir
A14: Tu sais que tu viens de… Yvetot | B14: Yvetot (76) | C14: Communauté de ville | D14: Non publié | E14: Rejoindre avec la Page, lire le règlement, écrire à l'admin avant de publier une seule annonce. (Lien relevé dans un article ici.fr de 2016 aujourd'hui indisponible ; source jointe : article ici.fr de 2019 sur le même réseau.) | F14: Ouvrir | G14: Voir
A15: Tu sais que tu viens de… Barentin | B15: Barentin (76) | C15: Communauté de ville | D15: Non publié | E15: Rejoindre avec la Page, lire le règlement, écrire à l'admin avant de publier une seule annonce. (Lien relevé dans un article ici.fr de 2016 aujourd'hui indisponible ; source jointe : article ici.fr de 2019 sur le même réseau.) | F15: Ouvrir | G15: Voir
A16: Tu sais que tu viens de… Bolbec | B16: Bolbec (76) | C16: Communauté de ville | D16: Non publié | E16: Rejoindre avec la Page, lire le règlement, écrire à l'admin avant de publier une seule annonce. (Lien relevé dans un article ici.fr de 2016 aujourd'hui indisponible ; source jointe : article ici.fr de 2019 sur le même réseau.) | F16: Ouvrir | G16: Voir
A17: Tu sais que tu viens de… Pavilly | B17: Pavilly (76) | C17: Communauté de ville | D17: Non publié | E17: Rejoindre avec la Page, lire le règlement, écrire à l'admin avant de publier une seule annonce. (Lien relevé dans un article ici.fr de 2016 aujourd'hui indisponible ; source jointe : article ici.fr de 2019 sur le même réseau.) | F17: Ouvrir | G17: Voir
... A23: Artisans et Auto-entrepreneurs | B23: France (B2B) | C23: Groupe pro | D23: ~5 400, privé (2023) | E23: Groupe privé (~5 400, 2023). Vérifier qu'il est réservé aux pros avant d'y publier le prix pro. Se présenter comme fournisseur ; pas de démarchage en message privé. | F23: Ouvrir | G23: Voir
A24: • Liens et effectifs viennent d'articles de presse (2016–2024) : vérifiez que chaque groupe existe toujours, son nom exact et son règlement une fois connecté.
A25: • Une Page ne peut que demander à rejoindre un groupe ; si les Pages ne sont pas admises, demandez à l'admin comment un professionnel peut publier.
A26: • En dehors de VendezVosMateriaux.fr et LES PRO DU BÂTIMENT, aucun groupe thématique (piscine, jardin, déstockage) ni groupe de Gennevilliers, du 95, du 78 ou du 93 n'a pu être confirmé : cherchez-les vous-même dans Facebook avec « travaux maison 92 », « piscine Île-de-France », « bons plans matériaux ».
A27: • Jamais d'extraction de membres ni de messages privés non sollicités aux membres (RGPD et règles de Facebook).

Sheet Contacts particuliers
A1: Date | B1: Source (Leboncoin, AlloVoisins, Instagram…) | C1: Ville | D1: Surface (m²) | E1: Usage | F1: Statut | G1: Prochaine action | H1: Notes (sans téléphone, e-mail ni adresse)
A2: Une ligne par demande de particulier. Ne notez pas ses coordonnées : elles restent dans la messagerie de la plateforme ou sur la facture.
A3: 13/10/2026 | B3: AlloVoisins | C3: À préciser | D3: 72 | E3: Terrasse (Patrick) | F3: À qualifier | G3: Confirmer s'il cherche aussi la pierre (pas seulement un poseur) avant toute réponse | H3: Réponse impossible sans Premier/essai ; voir allovoisins.md
A4: 13/10/2026 | B4: AlloVoisins | C4: Tremblay-en-France (93) | E4: À préciser (Francis) | F4: À qualifier | G4: Confirmer le besoin en fourniture de pierre | H4: Réponse impossible sans Premier/essai
A5: 13/10/2026 | B5: AlloVoisins | C5: Garches (92) | E5: À préciser (Sandra) | F5: À qualifier | G5: Confirmer le besoin en fourniture de pierre | H5: Réponse impossible sans Premier/essai
